<?xml version="1.0"?>
<robot name="one_link_robot">

  <link name="base_link">
    <visual>
      <geometry>
        <box size="0.12 0.11 0.003"/>
      </geometry>
    </visual>
  </link>

  <link name="lwheel">
    <visual>
      <geometry>
        <cylinder length="0.02" radius="0.035"/>
      </geometry>
      <origin rpy="0 1.570 0" xyz="0.01 0 0"/>
      <material name="blue">
        <color rgba="0 0 1 1"/>
      </material>
    </visual>
  </link>

  <link name="rwheel">
    <visual>
      <geometry>
        <cylinder length="0.02" radius="0.035"/>
      </geometry>
      <origin rpy="0 -1.570 0" xyz="-0.01 0 0"/>
      <material name="blue">
        <color rgba="0 0 1 1"/>
      </material>
    </visual>
  </link>

  <link name="cyl">
    <visual>
      <geometry>
        <cylinder length="0.025" radius="0.01"/>
      </geometry>
      <origin rpy="0 0 0" xyz="0 0 -0.0125"/>
    </visual>
  </link>

  <link name="sphere">
  <visual>
    <geometry>
      <sphere radius="0.01"/>
    </geometry>
    <origin rpy="0 0 0" xyz="0 0 0"/>
    <material name="green">
        <color rgba="0 1 0 1"/>
      </material>
  </visual>
</link>

  <joint name="joint1" type="continuous">
    <origin rpy="0 0 0" xyz="0.06 0.02 0"/>
    <parent link="base_link"/>
    <child link="lwheel"/>
    <axis xyz="1 0 0"/>
  </joint>

  <joint name="joint2" type="continuous">
    <origin rpy="0 0 0" xyz="-0.06 0.02 0"/>
    <parent link="base_link"/>
    <child link="rwheel"/>
    <axis xyz="1 0 0"/>
  </joint>

  <joint name="joint3" type="fixed">
    <origin rpy="0 0 0" xyz="0 -0.04 0"/>
    <parent link="base_link"/>
    <child link="cyl"/>
    <axis xyz="1 0 0"/>
  </joint>

  <joint name="joint4" type="fixed">
    <origin rpy="0 0 0" xyz="0 0 -0.025"/>
    <parent link="cyl"/>
    <child link="sphere"/>
    <axis xyz="1 0 0"/>
  </joint>

</robot>
